Workbook

Sheet DATOS
A1: SECTOR / ZONA | B1: ACTIVIDAD | C1: FAMILIA | D1: VENCE | E1: EST | F1: CAL | G1: CAMPO | H1: AMB | I1: BIM | J1: SEG | K1: CHECKS PENDIENTES | L1: TOTAL CHECKS | M1: ANTIGÜEDAD (días) | N1: CLAVE ORDEN | O1: LISTA TRELLO | P1: DÍA DEL CORTE | Q1: LINK TRELLO | S1: FUENTE Y TRAZABILIDAD
A2: 1CS13 | B2: CONCRETO EN FALSA ZAPATA | C2: Concreto | D2: =DATE(2026,8,26)+TIME(18,30,0) | E2: 0 | F2: 5 | G2: 0 | H2: 1 | I2: 0 | J2: 0 | K2: =IF($A2="","",SUM($E2:$J2)) | L2: 21 | M2: =IF($A2="","",MAX(0,ROUNDUP(DASHBOARD!$F$3-$D2,0))) | N2: =IF($A2="","",$K2+(5002-ROW())/10000) | O2: T. POR CERRAR | P2: AYER Y ANTES | Q2: https://trello.com/c/sec1trdc | S2: ="Trello — Tablero: CONSTRUCCIÓN DE AULAS · Listas: T. POR CERRAR ("&COUNTIF($P$2:$P$201,"AYER Y ANTES")&") y T. DEL DÍA ("&COUNTIF($P$2:$P$201,"HOY")&")"
A3: 1CS11 | B3: ACERO INFERIOR EN ZAPATAS | C3: Acero | D3: =DATE(2026,8,26)+TIME(18,30,0) | E3: 0 | F3: 4 | G3: 1 | H3: 2 | I3: 0 | J3: 0 | K3: =IF($A3="","",SUM($E3:$J3)) | L3: 18 | M3: =IF($A3="","",MAX(0,ROUNDUP(DASHBOARD!$F$3-$D3,0))) | N3: =IF($A3="","",$K3+(5002-ROW())/10000) | O3: T. POR CERRAR | P3: AYER Y ANTES | Q3: https://trello.com/c/ZBHQBgBG | S3: https://trello.com/b/zHM9mQvq/construcción-de-aulas
A4: 1CS6 | B4: ACERO VERTICAL DE COLUMNAS Y ESTRIBOS PARCIALES | C4: Acero | D4: =DATE(2026,8,26)+TIME(18,30,0) | E4: 0 | F4: 0 | G4: 0 | H4: 2 | I4: 0 | J4: 0 | K4: =IF($A4="","",SUM($E4:$J4)) | L4: 16 | M4: =IF($A4="","",MAX(0,ROUNDUP(DASHBOARD!$F$3-$D4,0))) | N4: =IF($A4="","",$K4+(5002-ROW())/10000) | O4: T. POR CERRAR | P4: AYER Y ANTES | Q4: https://trello.com/c/AgltFa8m | S4: ="Descarga de Trello: "&TEXT(DASHBOARD!$F$3,"dd/mm/yyyy hh:mm")&" h (hora local). Los checks pendientes por responsable provienen de los checklists de cada tarjeta (ítems no marcados)."
A5: 1CS5 | B5: ACERO DE VIGA DE CIMENTACIÓN | C5: Acero | D5: =DATE(2026,8,26)+TIME(18,30,0) | E5: 0 | F5: 0 | G5: 0 | H5: 2 | I5: 0 | J5: 0 | K5: =IF($A5="","",SUM($E5:$J5)) | L5: 18 | M5: =IF($A5="","",MAX(0,ROUNDUP(DASHBOARD!$F$3-$D5,0))) | N5: =IF($A5="","",$K5+(5002-ROW())/10000) | O5: T. POR CERRAR | P5: AYER Y ANTES | Q5: https://trello.com/c/nhoI3u1j
A6: 1CS5 | B6: ACERO SUPERIOR EN ZAPATAS | C6: Acero | D6: =DATE(2026,8,26)+TIME(18,30,0) | E6: 1 | F6: 0 | G6: 0 | H6: 3 | I6: 0 | J6: 0 | K6: =IF($A6="","",SUM($E6:$J6)) | L6: 22 | M6: =IF($A6="","",MAX(0,ROUNDUP(DASHBOARD!$F$3-$D6,0))) | N6: =IF($A6="","",$K6+(5002-ROW())/10000) | O6: T. POR CERRAR | P6: AYER Y ANTES | Q6: https://trello.com/c/v9ebbERg
A7: 1PS1 | B7: COMPLETADO DE ESTRIBOS EN COLUMNAS Y PLACAS | C7: Acero | D7: =DATE(2026,8,26)+TIME(18,30,0) | E7: 0 | F7: 0 | G7: 0 | H7: 2 | I7: 0 | J7: 5 | K7: =IF($A7="","",SUM($E7:$J7)) | L7: 26 | M7: =IF($A7="","",MAX(0,ROUNDUP(DASHBOARD!$F$3-$D7,0))) | N7: =IF($A7="","",$K7+(5002-ROW())/10000) | O7: T. POR CERRAR | P7: AYER Y ANTES | Q7: https://trello.com/c/QKxpbpkY
A8: 1CS2 | B8: RELLENO CON AFIRMADO COMPACTADO HASTA NIVEL DE ZAPATA | C8: Relleno | D8: =DATE(2026,8,26)+TIME(18,30,0) | E8: 0 | F8: 0 | G8: 0 | H8: 0 | I8: 0 | J8: 2 | K8: =IF($A8="","",SUM($E8:$J8)) | L8: 13 | M8: =IF($A8="","",MAX(0,ROUNDUP(DASHBOARD!$F$3-$D8,0))) | N8: =IF($A8="","",$K8+(5002-ROW())/10000) | O8: T. POR CERRAR | P8: AYER Y ANTES | Q8: https://trello.com/c/57IBCnhy
A9: 1CS4 | B9: ENCOFRADO DE ZAPATA Y VIGA DE CIMENTACIÓN | C9: Encofrado | D9: =DATE(2026,8,26)+TIME(18,30,0) | E9: 3 | F9: 5 | G9: 0 | H9: 1 | I9: 0 | J9: 0 | K9: =IF($A9="","",SUM($E9:$J9)) | L9: 17 | M9: =IF($A9="","",MAX(0,ROUNDUP(DASHBOARD!$F$3-$D9,0))) | N9: =IF($A9="","",$K9+(5002-ROW())/10000) | O9: T. POR CERRAR | P9: AYER Y ANTES | Q9: https://trello.com/c/YqZMtkzT
A10: 1CS14 | B10: ENCOFRADO DE FALSA ZAPATA | C10: Encofrado | D10: =DATE(2026,8,26)+TIME(18,30,0) | E10: 3 | F10: 7 | G10: 2 | H10: 1 | I10: 0 | J10: 0 | K10: =IF($A10="","",SUM($E10:$J10)) | L10: 18 | M10: =IF($A10="","",MAX(0,ROUNDUP(DASHBOARD!$F$3-$D10,0))) | N10: =IF($A10="","",$K10+(5002-ROW())/10000) | O10: T. POR CERRAR | P10: AYER Y ANTES | Q10: https://trello.com/c/MJSPIyhO
A11: 1CS15 | B11: TRAZO Y REPLANTEO PARA EXCAVACIÓN DE CIMENTACIONES | C11: Trazo | D11: =DATE(2026,8,26)+TIME(18,30,0) | E11: 3 | F11: 5 | G11: 0 | H11: 0 | I11: 0 | J11: 0 | K11: =IF($A11="","",SUM($E11:$J11)) | L11: 11 | M11: =IF($A11="","",MAX(0,ROUNDUP(DASHBOARD!$F$3-$D11,0))) | N11: =IF($A11="","",$K11+(5002-ROW())/10000) | O11: T. POR CERRAR | P11: AYER Y ANTES | Q11: https://trello.com/c/hFjlCxrD
A12: 1CS15 | B12: EXCAVACIÓN DE CIMENTACIONES | C12: Excavación | D12: =DATE(2026,8,26)+TIME(18,30,0) | E12: 4 | F12: 4 | G12: 0 | H12: 2 | I12: 0 | J12: 0 | K12: =IF($A12="","",SUM($E12:$J12)) | L12: 21 | M12: =IF($A12="","",MAX(0,ROUNDUP(DASHBOARD!$F$3-$D12,0))) | N12: =IF($A12="","",$K12+(5002-ROW())/10000) | O12: T. POR CERRAR | P12: AYER Y ANTES | Q12: https://trello.com/c/MYWqBFxs
A13: 1CS12 | B13: ACERO INFERIOR EN ZAPATAS | C13: Acero | D13: =DATE(2026,8,27)+TIME(18,30,0) | E13: 7 | F13: 4 | G13: 1 | H13: 2 | I13: 0 | J13: 0 | K13: =IF($A13="","",SUM($E13:$J13)) | L13: 18 | M13: =IF($A13="","",MAX(0,ROUNDUP(DASHBOARD!$F$3-$D13,0))) | N13: =IF($A13="","",$K13+(5002-ROW())/10000) | O13: T. DEL DÍA ACERO | P13: HOY | Q13: https://trello.com/c/aOot1TlU
A14: 1CS11 | B14: ACERO VERTICAL DE COLUMNAS Y ESTRIBOS PARCIALES | C14: Acero | D14: =DATE(2026,8,27)+TIME(18,30,0) | E14: 5 | F14: 4 | G14: 2 | H14: 2 | I14: 0 | J14: 3 | K14: =IF($A14="","",SUM($E14:$J14)) | L14: 16 | M14: =IF($A14="","",MAX(0,ROUNDUP(DASHBOARD!$F$3-$D14,0))) | N14: =IF($A14="","",$K14+(5002-ROW())/10000) | O14: T. DEL DÍA ACERO | P14: HOY | Q14: https://trello.com/c/uRdhIpHd
A15: 1CS6 | B15: ACERO DE VIGA DE CIMENTACIÓN | C15: Acero | D15: =DATE(2026,8,27)+TIME(18,30,0) | E15: 7 | F15: 4 | G15: 2 | H15: 2 | I15: 0 | J15: 3 | K15: =IF($A15="","",SUM($E15:$J15)) | L15: 18 | M15: =IF($A15="","",MAX(0,ROUNDUP(DASHBOARD!$F$3-$D15,0))) | N15: =IF($A15="","",$K15+(5002-ROW())/10000) | O15: T. DEL DÍA ACERO | P15: HOY | Q15: https://trello.com/c/jP8NrRJ1
A16: 1CS6 | B16: ACERO SUPERIOR EN ZAPATAS | C16: Acero | D16: =DATE(2026,8,27)+TIME(18,30,0) | E16: 2 | F16: 5 | G16: 1 | H16: 3 | I16: 0 | J16: 0 | K16: =IF($A16="","",SUM($E16:$J16)) | L16: 22 | M16: =IF($A16="","",MAX(0,ROUNDUP(DASHBOARD!$F$3-$D16,0))) | N16: =IF($A16="","",$K16+(5002-ROW())/10000) | O16: T. DEL DÍA ACERO | P16: HOY | Q16: https://trello.com/c/BQYYbpGR
A17: 1PS2 | B17: COMPLETADO DE ESTRIBOS EN COLUMNAS Y PLACAS | C17: Acero | D17: =DATE(2026,8,27)+TIME(18,30,0) | E17: 5 | F17: 5 | G17: 5 | H17: 2 | I17: 4 | J17: 5 | K17: =IF($A17="","",SUM($E17:$J17)) | L17: 26 | M17: =IF($A17="","",MAX(0,ROUNDUP(DASHBOARD!$F$3-$D17,0))) | N17: =IF($A17="","",$K17+(5002-ROW())/10000) | O17: T. DEL DÍA ACERO | P17: HOY | Q17: https://trello.com/c/g8Agnfym
A18: 1CS15 | B18: ENCOFRADO DE FALSA ZAPATA | C18: Encofrado | D18: =DATE(2026,8,27)+TIME(18,30,0) | E18: 3 | F18: 7 | G18: 2 | H18: 1 | I18: 2 | J18: 3 | K18: =IF($A18="","",SUM($E18:$J18)) | L18: 18 | M18: =IF($A18="","",MAX(0,ROUNDUP(DASHBOARD!$F$3-$D18,0))) | N18: =IF($A18="","",$K18+(5002-ROW())/10000) | O18: T. DEL DÍA ENCOFRADO | P18: HOY | Q18: https://trello.com/c/3ajLlFsT
A19: 1CS5 | B19: ENCOFRADO DE ZAPATA Y VIGA DE CIMENTACIÓN | C19: Encofrado | D19: =DATE(2026,8,27)+TIME(18,30,0) | E19: 3 | F19: 5 | G19: 4 | H19: 1 | I19: 2 | J19: 2 | K19: =IF($A19="","",SUM($E19:$J19)) | L19: 17 | M19: =IF($A19="","",MAX(0,ROUNDUP(DASHBOARD!$F$3-$D19,0))) | N19: =IF($A19="","",$K19+(5002-ROW())/10000) | O19: T. DEL DÍA ENCOFRADO | P19: HOY | Q19: https://trello.com/c/OXb5t9ie
A20: 1PS1 | B20: ENCOFRADO DE COLUMNAS Y PLACAS | C20: Encofrado | D20: =DATE(2026,8,27)+TIME(18,30,0) | E20: 3 | F20: 8 | G20: 6 | H20: 1 | I20: 0 | J20: 2 | K20: =IF($A20="","",SUM($E20:$J20)) | L20: 20 | M20: =IF($A20="","",MAX(0,ROUNDUP(DASHBOARD!$F$3-$D20,0))) | N20: =IF($A20="","",$K20+(5002-ROW())/10000) | O20: T. DEL DÍA ENCOFRADO | P20: HOY | Q20: https://trello.com/c/0j71oTjs
A21: 1CS14 | B21: CONCRETO EN FALSA ZAPATA | C21: Concreto | D21: =DATE(2026,8,27)+TIME(18,30,0) | E21: 3 | F21: 5 | G21: 7 | H21: 2 | I21: 1 | J21: 3 | K21: =IF($A21="","",SUM($E21:$J21)) | L21: 21 | M21: =IF($A21="","",MAX(0,ROUNDUP(DASHBOARD!$F$3-$D21,0))) | N21: =IF($A21="","",$K21+(5002-ROW())/10000) | O21: T. DEL DÍA CONCRETO Y MORTERO | P21: HOY | Q21: https://trello.com/c/2AyY2l2C
A22: 1CS4 | B22: CONCRETO DE ZAPATA Y VIGA DE CIMENTACIÓN | C22: Concreto | D22: =DATE(2026,8,27)+TIME(18,30,0) | E22: 3 | F22: 5 | G22: 5 | H22: 1 | I22: 1 | J22: 2 | K22: =IF($A22="","",SUM($E22:$J22)) | L22: 17 | M22: =IF($A22="","",MAX(0,ROUNDUP(DASHBOARD!$F$3-$D22,0))) | N22: =IF($A22="","",$K22+(5002-ROW())/10000) | O22: T. DEL DÍA CONCRETO Y MORTERO | P22: HOY | Q22: https://trello.com/c/SUsennNc
A23: 1CS13 | B23: RELLENO CON AFIRMADO COMPACTADO HASTA NIVEL DE FALSA ZAPATA | C23: Relleno | D23: =DATE(2026,8,27)+TIME(18,30,0) | E23: 0 | F23: 4 | G23: 4 | H23: 1 | I23: 0 | J23: 1 | K23: =IF($A23="","",SUM($E23:$J23)) | L23: 11 | M23: =IF($A23="","",MAX(0,ROUNDUP(DASHBOARD!$F$3-$D23,0))) | N23: =IF($A23="","",$K23+(5002-ROW())/10000) | O23: T. DEL DÍA VARIOS | P23: HOY | Q23: https://trello.com/c/HI91I8Pi
A24: 1CS7 | B24: EXCAVACIÓN DE CIMENTACIONES | C24: Excavación | D24: =DATE(2026,8,27)+TIME(18,30,0) | E24: 4 | F24: 4 | G24: 6 | H24: 2 | I24: 2 | J24: 3 | K24: =IF($A24="","",SUM($E24:$J24)) | L24: 21 | M24: =IF($A24="","",MAX(0,ROUNDUP(DASHBOARD!$F$3-$D24,0))) | N24: =IF($A24="","",$K24+(5002-ROW())/10000) | O24: T. DEL DÍA VARIOS | P24: HOY | Q24: https://trello.com/c/OWZas5ga
... A27: 1PS2 | B27: TRAZO Y REPLANTEO DE COLUMNAS Y PLACAS | C27: Trazo | D27: =DATE(2026,8,27)+TIME(18,30,0) | E27: 3 | F27: 6 | G27: 1 | H27: 0 | I27: 3 | J27: 0 | K27: =IF($A27="","",SUM($E27:$J27)) | L27: 13 | M27: =IF($A27="","",MAX(0,ROUNDUP(DASHBOARD!$F$3-$D27,0))) | N27: =IF($A27="","",$K27+(5002-ROW())/10000) | O27: T. DEL DÍA VARIOS | P27: HOY | Q27: https://trello.com/c/Ur6rObnM
K28: =IF($A28="","",SUM($E28:$J28)) | M28: =IF($A28="","",MAX(0,ROUNDUP(DASHBOARD!$F$3-$D28,0))) | N28: =IF($A28="","",$K28+(5002-ROW())/10000)
K29: =IF($A29="","",SUM($E29:$J29)) | M29: =IF($A29="","",MAX(0,ROUNDUP(DASHBOARD!$F$3-$D29,0))) | N29: =IF($A29="","",$K29+(5002-ROW())/10000)
K30: =IF($A30="","",SUM($E30:$J30)) | M30: =IF($A30="","",MAX(0,ROUNDUP(DASHBOARD!$F$3-$D30,0))) | N30: =IF($A30="","",$K30+(5002-ROW())/10000)
K31: =IF($A31="","",SUM($E31:$J31)) | M31: =IF($A31="","",MAX(0,ROUNDUP(DASHBOARD!$F$3-$D31,0))) | N31: =IF($A31="","",$K31+(5002-ROW())/10000)
K32: =IF($A32="","",SUM($E32:$J32)) | M32: =IF($A32="","",MAX(0,ROUNDUP(DASHBOARD!$F$3-$D32,0))) | N32: =IF($A32="","",$K32+(5002-ROW())/10000)
K33: =IF($A33="","",SUM($E33:$J33)) | M33: =IF($A33="","",MAX(0,ROUNDUP(DASHBOARD!$F$3-$D33,0))) | N33: =IF($A33="","",$K33+(5002-ROW())/10000)
K34: =IF($A34="","",SUM($E34:$J34)) | M34: =IF($A34="","",MAX(0,ROUNDUP(DASHBOARD!$F$3-$D34,0))) | N34: =IF($A34="","",$K34+(5002-ROW())/10000)
K35: =IF($A35="","",SUM($E35:$J35)) | M35: =IF($A35="","",MAX(0,ROUNDUP(DASHBOARD!$F$3-$D35,0))) | N35: =IF($A35="","",$K35+(5002-ROW())/10000)
K36: =IF($A36="","",SUM($E36:$J36)) | M36: =IF($A36="","",MAX(0,ROUNDUP(DASHBOARD!$F$3-$D36,0))) | N36: =IF($A36="","",$K36+(5002-ROW())/10000)
K37: =IF($A37="","",SUM($E37:$J37)) | M37: =IF($A37="","",MAX(0,ROUNDUP(DASHBOARD!$F$3-$D37,0))) | N37: =IF($A37="","",$K37+(5002-ROW())/10000)
K38: =IF($A38="","",SUM($E38:$J38)) | M38: =IF($A38="","",MAX(0,ROUNDUP(DASHBOARD!$F$3-$D38,0))) | N38: =IF($A38="","",$K38+(5002-ROW())/10000)
K39: =IF($A39="","",SUM($E39:$J39)) | M39: =IF($A39="","",MAX(0,ROUNDUP(DASHBOARD!$F$3-$D39,0))) | N39: =IF($A39="","",$K39+(5002-ROW())/10000)
... K5000: =IF($A5000="","",SUM($E5000:$J5000)) | M5000: =IF($A5000="","",MAX(0,ROUNDUP(DASHBOARD!$F$3-$D5000,0))) | N5000: =IF($A5000="","",$K5000+(5002-ROW())/10000)

Sheet DASHBOARD
B2: T. POR CERRAR + T. DEL DÍA | F2: FECHA DE CORTE | H2: TABLERO | L2: ANTIGÜEDAD DE TARJETAS | N2: ■ Vencidas > 1 día | Q2: =$U$22 | R2: =$V$22 | T2: TABLAS DE APOYO — FUENTE DE LOS GRÁFICOS
B3: CONTROL OPERATIVO – LAST PLANNER | F3: =IFERROR(MAX(DATOS!$D$2:$D$5001),TODAY()) | H3: CONSTRUCCIÓN DE AULAS | N3: ■ Vencidas 1 día (ayer) | Q3: =$U$23 | R3: =$V$23
B4: Corte de pendientes: vencidos de ayer hacia atrás vs. actividades programadas hoy | L4: TOTAL | M4: =SUM(Q2:Q4) | N4: ■ Vence hoy | Q4: =$U$24 | R4: =$V$24 | T4: CHECKS PENDIENTES POR RESPONSABLE
T5: RESPONSABLE | U5: AYER Y ANTES | V5: HOY | W5: TOTAL
B6: =COUNTA(DATOS!$A$2:$A$5001) | C6: =SUM(DATOS!$K$2:$K$5001) | T6: EST | U6: =SUMIF(DATOS!$P$2:$P$5001,U$5,DATOS!$E$2:$E$5001) | V6: =SUMIF(DATOS!$P$2:$P$5001,V$5,DATOS!$E$2:$E$5001) | W6: =U6+V6
B7: TARJETAS SIN CERRAR (AYER Y ANTES + HOY) | C7: CHECKS PENDIENTES (TOTAL DEL CORTE) | T7: CAL | U7: =SUMIF(DATOS!$P$2:$P$5001,U$5,DATOS!$F$2:$F$5001) | V7: =SUMIF(DATOS!$P$2:$P$5001,V$5,DATOS!$F$2:$F$5001) | W7: =U7+V7
T8: CAMP | U8: =SUMIF(DATOS!$P$2:$P$5001,U$5,DATOS!$G$2:$G$5001) | V8: =SUMIF(DATOS!$P$2:$P$5001,V$5,DATOS!$G$2:$G$5001) | W8: =U8+V8
T9: AMB | U9: =SUMIF(DATOS!$P$2:$P$5001,U$5,DATOS!$H$2:$H$5001) | V9: =SUMIF(DATOS!$P$2:$P$5001,V$5,DATOS!$H$2:$H$5001) | W9: =U9+V9
T10: BIM | U10: =SUMIF(DATOS!$P$2:$P$5001,U$5,DATOS!$I$2:$I$5001) | V10: =SUMIF(DATOS!$P$2:$P$5001,V$5,DATOS!$I$2:$I$5001) | W10: =U10+V10
T11: SSOMA | U11: =SUMIF(DATOS!$P$2:$P$5001,U$5,DATOS!$J$2:$J$5001) | V11: =SUMIF(DATOS!$P$2:$P$5001,V$5,DATOS!$J$2:$J$5001) | W11: =U11+V11
B12: DETALLE DE TARJETAS — T. POR CERRAR (AYER Y ANTES) Y T. DEL DÍA (HOY) | T12: TOTAL | U12: =SUM(U6:U11) | V12: =SUM(V6:V11) | W12: =SUM(W6:W11)
B13: SECTOR / ZONA | C13: ACTIVIDAD | H13: FAMILIA | I13: VENCE | J13: ANTIGÜEDAD (días) | K13: CHECKS PENDIENTES | L13: PENDIENTES POR RESPONSABLE | R13: DÍA DEL CORTE
L14: Est. | M14: Cal. | N14: Campo | O14: Amb. | P14: BIM | Q14: Seg.
B15: {=IF(INDEX(DATOS!$A$1:$A$201,ROW()-12)="","",INDEX(DATOS!$A$1:$A$201,ROW()-12))} | C15: {=IF(INDEX(DATOS!$B$1:$B$201,ROW()-12)="","",INDEX(DATOS!$B$1:$B$201,ROW()-12))} | H15: {=IF(INDEX(DATOS!$C$1:$C$201,ROW()-12)="","",INDEX(DATOS!$C$1:$C$201,ROW()-12))} | I15: {=IF(INDEX(DATOS!$D$1:$D$201,ROW()-12)="","",INDEX(DATOS!$D$1:$D$201,ROW()-12))} | J15: {=IF(INDEX(DATOS!$M$1:$M$201,ROW()-12)="","",INDEX(DATOS!$M$1:$M$201,ROW()-12))} | K15: {=IF(INDEX(DATOS!$K$1:$K$201,ROW()-12)="","",INDEX(DATOS!$K$1:$K$201,ROW()-12))} | L15: {=IF(INDEX(DATOS!$E$1:$E$201,ROW()-12)="","",INDEX(DATOS!$E$1:$E$201,ROW()-12))} | M15: {=IF(INDEX(DATOS!$F$1:$F$201,ROW()-12)="","",INDEX(DATOS!$F$1:$F$201,ROW()-12))} | N15: {=IF(INDEX(DATOS!$G$1:$G$201,ROW()-12)="","",INDEX(DATOS!$G$1:$G$201,ROW()-12))} | O15: {=IF(INDEX(DATOS!$H$1:$H$201,ROW()-12)="","",INDEX(DATOS!$H$1:$H$201,ROW()-12))} | P15: {=IF(INDEX(DATOS!$I$1:$I$201,ROW()-12)="","",INDEX(DATOS!$I$1:$I$201,ROW()-12))} | Q15: {=IF(INDEX(DATOS!$J$1:$J$201,ROW()-12)="","",INDEX(DATOS!$J$1:$J$201,ROW()-12))} | R15: {=IF(INDEX(DATOS!$P$1:$P$201,ROW()-12)="","",INDEX(DATOS!$P$1:$P$201,ROW()-12))}
B16: {=IF(INDEX(DATOS!$A$1:$A$201,ROW()-12)="","",INDEX(DATOS!$A$1:$A$201,ROW()-12))} | C16: {=IF(INDEX(DATOS!$B$1:$B$201,ROW()-12)="","",INDEX(DATOS!$B$1:$B$201,ROW()-12))} | H16: {=IF(INDEX(DATOS!$C$1:$C$201,ROW()-12)="","",INDEX(DATOS!$C$1:$C$201,ROW()-12))} | I16: {=IF(INDEX(DATOS!$D$1:$D$201,ROW()-12)="","",INDEX(DATOS!$D$1:$D$201,ROW()-12))} | J16: {=IF(INDEX(DATOS!$M$1:$M$201,ROW()-12)="","",INDEX(DATOS!$M$1:$M$201,ROW()-12))} | K16: {=IF(INDEX(DATOS!$K$1:$K$201,ROW()-12)="","",INDEX(DATOS!$K$1:$K$201,ROW()-12))} | L16: {=IF(INDEX(DATOS!$E$1:$E$201,ROW()-12)="","",INDEX(DATOS!$E$1:$E$201,ROW()-12))} | M16: {=IF(INDEX(DATOS!$F$1:$F$201,ROW()-12)="","",INDEX(DATOS!$F$1:$F$201,ROW()-12))} | N16: {=IF(INDEX(DATOS!$G$1:$G$201,ROW()-12)="","",INDEX(DATOS!$G$1:$G$201,ROW()-12))} | O16: {=IF(INDEX(DATOS!$H$1:$H$201,ROW()-12)="","",INDEX(DATOS!$H$1:$H$201,ROW()-12))} | P16: {=IF(INDEX(DATOS!$I$1:$I$201,ROW()-12)="","",INDEX(DATOS!$I$1:$I$201,ROW()-12))} | Q16: {=IF(INDEX(DATOS!$J$1:$J$201,ROW()-12)="","",INDEX(DATOS!$J$1:$J$201,ROW()-12))} | R16: {=IF(INDEX(DATOS!$P$1:$P$201,ROW()-12)="","",INDEX(DATOS!$P$1:$P$201,ROW()-12))}
B17: {=IF(INDEX(DATOS!$A$1:$A$201,ROW()-12)="","",INDEX(DATOS!$A$1:$A$201,ROW()-12))} | C17: {=IF(INDEX(DATOS!$B$1:$B$201,ROW()-12)="","",INDEX(DATOS!$B$1:$B$201,ROW()-12))} | H17: {=IF(INDEX(DATOS!$C$1:$C$201,ROW()-12)="","",INDEX(DATOS!$C$1:$C$201,ROW()-12))} | I17: {=IF(INDEX(DATOS!$D$1:$D$201,ROW()-12)="","",INDEX(DATOS!$D$1:$D$201,ROW()-12))} | J17: {=IF(INDEX(DATOS!$M$1:$M$201,ROW()-12)="","",INDEX(DATOS!$M$1:$M$201,ROW()-12))} | K17: {=IF(INDEX(DATOS!$K$1:$K$201,ROW()-12)="","",INDEX(DATOS!$K$1:$K$201,ROW()-12))} | L17: {=IF(INDEX(DATOS!$E$1:$E$201,ROW()-12)="","",INDEX(DATOS!$E$1:$E$201,ROW()-12))} | M17: {=IF(INDEX(DATOS!$F$1:$F$201,ROW()-12)="","",INDEX(DATOS!$F$1:$F$201,ROW()-12))} | N17: {=IF(INDEX(DATOS!$G$1:$G$201,ROW()-12)="","",INDEX(DATOS!$G$1:$G$201,ROW()-12))} | O17: {=IF(INDEX(DATOS!$H$1:$H$201,ROW()-12)="","",INDEX(DATOS!$H$1:$H$201,ROW()-12))} | P17: {=IF(INDEX(DATOS!$I$1:$I$201,ROW()-12)="","",INDEX(DATOS!$I$1:$I$201,ROW()-12))} | Q17: {=IF(INDEX(DATOS!$J$1:$J$201,ROW()-12)="","",INDEX(DATOS!$J$1:$J$201,ROW()-12))} | R17: {=IF(INDEX(DATOS!$P$1:$P$201,ROW()-12)="","",INDEX(DATOS!$P$1:$P$201,ROW()-12))}
B18: {=IF(INDEX(DATOS!$A$1:$A$201,ROW()-12)="","",INDEX(DATOS!$A$1:$A$201,ROW()-12))} | C18: {=IF(INDEX(DATOS!$B$1:$B$201,ROW()-12)="","",INDEX(DATOS!$B$1:$B$201,ROW()-12))} | H18: {=IF(INDEX(DATOS!$C$1:$C$201,ROW()-12)="","",INDEX(DATOS!$C$1:$C$201,ROW()-12))} | I18: {=IF(INDEX(DATOS!$D$1:$D$201,ROW()-12)="","",INDEX(DATOS!$D$1:$D$201,ROW()-12))} | J18: {=IF(INDEX(DATOS!$M$1:$M$201,ROW()-12)="","",INDEX(DATOS!$M$1:$M$201,ROW()-12))} | K18: {=IF(INDEX(DATOS!$K$1:$K$201,ROW()-12)="","",INDEX(DATOS!$K$1:$K$201,ROW()-12))} | L18: {=IF(INDEX(DATOS!$E$1:$E$201,ROW()-12)="","",INDEX(DATOS!$E$1:$E$201,ROW()-12))} | M18: {=IF(INDEX(DATOS!$F$1:$F$201,ROW()-12)="","",INDEX(DATOS!$F$1:$F$201,ROW()-12))} | N18: {=IF(INDEX(DATOS!$G$1:$G$201,ROW()-12)="","",INDEX(DATOS!$G$1:$G$201,ROW()-12))} | O18: {=IF(INDEX(DATOS!$H$1:$H$201,ROW()-12)="","",INDEX(DATOS!$H$1:$H$201,ROW()-12))} | P18: {=IF(INDEX(DATOS!$I$1:$I$201,ROW()-12)="","",INDEX(DATOS!$I$1:$I$201,ROW()-12))} | Q18: {=IF(INDEX(DATOS!$J$1:$J$201,ROW()-12)="","",INDEX(DATOS!$J$1:$J$201,ROW()-12))} | R18: {=IF(INDEX(DATOS!$P$1:$P$201,ROW()-12)="","",INDEX(DATOS!$P$1:$P$201,ROW()-12))}
B19: {=IF(INDEX(DATOS!$A$1:$A$201,ROW()-12)="","",INDEX(DATOS!$A$1:$A$201,ROW()-12))} | C19: {=IF(INDEX(DATOS!$B$1:$B$201,ROW()-12)="","",INDEX(DATOS!$B$1:$B$201,ROW()-12))} | H19: {=IF(INDEX(DATOS!$C$1:$C$201,ROW()-12)="","",INDEX(DATOS!$C$1:$C$201,ROW()-12))} | I19: {=IF(INDEX(DATOS!$D$1:$D$201,ROW()-12)="","",INDEX(DATOS!$D$1:$D$201,ROW()-12))} | J19: {=IF(INDEX(DATOS!$M$1:$M$201,ROW()-12)="","",INDEX(DATOS!$M$1:$M$201,ROW()-12))} | K19: {=IF(INDEX(DATOS!$K$1:$K$201,ROW()-12)="","",INDEX(DATOS!$K$1:$K$201,ROW()-12))} | L19: {=IF(INDEX(DATOS!$E$1:$E$201,ROW()-12)="","",INDEX(DATOS!$E$1:$E$201,ROW()-12))} | M19: {=IF(INDEX(DATOS!$F$1:$F$201,ROW()-12)="","",INDEX(DATOS!$F$1:$F$201,ROW()-12))} | N19: {=IF(INDEX(DATOS!$G$1:$G$201,ROW()-12)="","",INDEX(DATOS!$G$1:$G$201,ROW()-12))} | O19: {=IF(INDEX(DATOS!$H$1:$H$201,ROW()-12)="","",INDEX(DATOS!$H$1:$H$201,ROW()-12))} | P19: {=IF(INDEX(DATOS!$I$1:$I$201,ROW()-12)="","",INDEX(DATOS!$I$1:$I$201,ROW()-12))} | Q19: {=IF(INDEX(DATOS!$J$1:$J$201,ROW()-12)="","",INDEX(DATOS!$J$1:$J$201,ROW()-12))} | R19: {=IF(INDEX(DATOS!$P$1:$P$201,ROW()-12)="","",INDEX(DATOS!$P$1:$P$201,ROW()-12))}
B20: {=IF(INDEX(DATOS!$A$1:$A$201,ROW()-12)="","",INDEX(DATOS!$A$1:$A$201,ROW()-12))} | C20: {=IF(INDEX(DATOS!$B$1:$B$201,ROW()-12)="","",INDEX(DATOS!$B$1:$B$201,ROW()-12))} | H20: {=IF(INDEX(DATOS!$C$1:$C$201,ROW()-12)="","",INDEX(DATOS!$C$1:$C$201,ROW()-12))} | I20: {=IF(INDEX(DATOS!$D$1:$D$201,ROW()-12)="","",INDEX(DATOS!$D$1:$D$201,ROW()-12))} | J20: {=IF(INDEX(DATOS!$M$1:$M$201,ROW()-12)="","",INDEX(DATOS!$M$1:$M$201,ROW()-12))} | K20: {=IF(INDEX(DATOS!$K$1:$K$201,ROW()-12)="","",INDEX(DATOS!$K$1:$K$201,ROW()-12))} | L20: {=IF(INDEX(DATOS!$E$1:$E$201,ROW()-12)="","",INDEX(DATOS!$E$1:$E$201,ROW()-12))} | M20: {=IF(INDEX(DATOS!$F$1:$F$201,ROW()-12)="","",INDEX(DATOS!$F$1:$F$201,ROW()-12))} | N20: {=IF(INDEX(DATOS!$G$1:$G$201,ROW()-12)="","",INDEX(DATOS!$G$1:$G$201,ROW()-12))} | O20: {=IF(INDEX(DATOS!$H$1:$H$201,ROW()-12)="","",INDEX(DATOS!$H$1:$H$201,ROW()-12))} | P20: {=IF(INDEX(DATOS!$I$1:$I$201,ROW()-12)="","",INDEX(DATOS!$I$1:$I$201,ROW()-12))} | Q20: {=IF(INDEX(DATOS!$J$1:$J$201,ROW()-12)="","",INDEX(DATOS!$J$1:$J$201,ROW()-12))} | R20: {=IF(INDEX(DATOS!$P$1:$P$201,ROW()-12)="","",INDEX(DATOS!$P$1:$P$201,ROW()-12))} | T20: ANTIGÜEDAD DE TARJETAS (TODO EL CORTE)
B21: {=IF(INDEX(DATOS!$A$1:$A$201,ROW()-12)="","",INDEX(DATOS!$A$1:$A$201,ROW()-12))} | C21: {=IF(INDEX(DATOS!$B$1:$B$201,ROW()-12)="","",INDEX(DATOS!$B$1:$B$201,ROW()-12))} | H21: {=IF(INDEX(DATOS!$C$1:$C$201,ROW()-12)="","",INDEX(DATOS!$C$1:$C$201,ROW()-12))} | I21: {=IF(INDEX(DATOS!$D$1:$D$201,ROW()-12)="","",INDEX(DATOS!$D$1:$D$201,ROW()-12))} | J21: {=IF(INDEX(DATOS!$M$1:$M$201,ROW()-12)="","",INDEX(DATOS!$M$1:$M$201,ROW()-12))} | K21: {=IF(INDEX(DATOS!$K$1:$K$201,ROW()-12)="","",INDEX(DATOS!$K$1:$K$201,ROW()-12))} | L21: {=IF(INDEX(DATOS!$E$1:$E$201,ROW()-12)="","",INDEX(DATOS!$E$1:$E$201,ROW()-12))} | M21: {=IF(INDEX(DATOS!$F$1:$F$201,ROW()-12)="","",INDEX(DATOS!$F$1:$F$201,ROW()-12))} | N21: {=IF(INDEX(DATOS!$G$1:$G$201,ROW()-12)="","",INDEX(DATOS!$G$1:$G$201,ROW()-12))} | O21: {=IF(INDEX(DATOS!$H$1:$H$201,ROW()-12)="","",INDEX(DATOS!$H$1:$H$201,ROW()-12))} | P21: {=IF(INDEX(DATOS!$I$1:$I$201,ROW()-12)="","",INDEX(DATOS!$I$1:$I$201,ROW()-12))} | Q21: {=IF(INDEX(DATOS!$J$1:$J$201,ROW()-12)="","",INDEX(DATOS!$J$1:$J$201,ROW()-12))} | R21: {=IF(INDEX(DATOS!$P$1:$P$201,ROW()-12)="","",INDEX(DATOS!$P$1:$P$201,ROW()-12))} | T21: RANGO | U21: TARJETAS | V21: %
B22: {=IF(INDEX(DATOS!$A$1:$A$201,ROW()-12)="","",INDEX(DATOS!$A$1:$A$201,ROW()-12))} | C22: {=IF(INDEX(DATOS!$B$1:$B$201,ROW()-12)="","",INDEX(DATOS!$B$1:$B$201,ROW()-12))} | H22: {=IF(INDEX(DATOS!$C$1:$C$201,ROW()-12)="","",INDEX(DATOS!$C$1:$C$201,ROW()-12))} | I22: {=IF(INDEX(DATOS!$D$1:$D$201,ROW()-12)="","",INDEX(DATOS!$D$1:$D$201,ROW()-12))} | J22: {=IF(INDEX(DATOS!$M$1:$M$201,ROW()-12)="","",INDEX(DATOS!$M$1:$M$201,ROW()-12))} | K22: {=IF(INDEX(DATOS!$K$1:$K$201,ROW()-12)="","",INDEX(DATOS!$K$1:$K$201,ROW()-12))} | L22: {=IF(INDEX(DATOS!$E$1:$E$201,ROW()-12)="","",INDEX(DATOS!$E$1:$E$201,ROW()-12))} | M22: {=IF(INDEX(DATOS!$F$1:$F$201,ROW()-12)="","",INDEX(DATOS!$F$1:$F$201,ROW()-12))} | N22: {=IF(INDEX(DATOS!$G$1:$G$201,ROW()-12)="","",INDEX(DATOS!$G$1:$G$201,ROW()-12))} | O22: {=IF(INDEX(DATOS!$H$1:$H$201,ROW()-12)="","",INDEX(DATOS!$H$1:$H$201,ROW()-12))} | P22: {=IF(INDEX(DATOS!$I$1:$I$201,ROW()-12)="","",INDEX(DATOS!$I$1:$I$201,ROW()-12))} | Q22: {=IF(INDEX(DATOS!$J$1:$J$201,ROW()-12)="","",INDEX(DATOS!$J$1:$J$201,ROW()-12))} | R22: {=IF(INDEX(DATOS!$P$1:$P$201,ROW()-12)="","",INDEX(DATOS!$P$1:$P$201,ROW()-12))} | T22: Vencidas > 1 día | U22: =COUNTIF(DATOS!$M$2:$M$5001,">1") | V22: =U22/$U$25
B23: {=IF(INDEX(DATOS!$A$1:$A$201,ROW()-12)="","",INDEX(DATOS!$A$1:$A$201,ROW()-12))} | C23: {=IF(INDEX(DATOS!$B$1:$B$201,ROW()-12)="","",INDEX(DATOS!$B$1:$B$201,ROW()-12))} | H23: {=IF(INDEX(DATOS!$C$1:$C$201,ROW()-12)="","",INDEX(DATOS!$C$1:$C$201,ROW()-12))} | I23: {=IF(INDEX(DATOS!$D$1:$D$201,ROW()-12)="","",INDEX(DATOS!$D$1:$D$201,ROW()-12))} | J23: {=IF(INDEX(DATOS!$M$1:$M$201,ROW()-12)="","",INDEX(DATOS!$M$1:$M$201,ROW()-12))} | K23: {=IF(INDEX(DATOS!$K$1:$K$201,ROW()-12)="","",INDEX(DATOS!$K$1:$K$201,ROW()-12))} | L23: {=IF(INDEX(DATOS!$E$1:$E$201,ROW()-12)="","",INDEX(DATOS!$E$1:$E$201,ROW()-12))} | M23: {=IF(INDEX(DATOS!$F$1:$F$201,ROW()-12)="","",INDEX(DATOS!$F$1:$F$201,ROW()-12))} | N23: {=IF(INDEX(DATOS!$G$1:$G$201,ROW()-12)="","",INDEX(DATOS!$G$1:$G$201,ROW()-12))} | O23: {=IF(INDEX(DATOS!$H$1:$H$201,ROW()-12)="","",INDEX(DATOS!$H$1:$H$201,ROW()-12))} | P23: {=IF(INDEX(DATOS!$I$1:$I$201,ROW()-12)="","",INDEX(DATOS!$I$1:$I$201,ROW()-12))} | Q23: {=IF(INDEX(DATOS!$J$1:$J$201,ROW()-12)="","",INDEX(DATOS!$J$1:$J$201,ROW()-12))} | R23: {=IF(INDEX(DATOS!$P$1:$P$201,ROW()-12)="","",INDEX(DATOS!$P$1:$P$201,ROW()-12))} | T23: Vencidas 1 día | U23: =COUNTIF(DATOS!$M$2:$M$5001,"=1") | V23: =U23/$U$25
B24: {=IF(INDEX(DATOS!$A$1:$A$201,ROW()-12)="","",INDEX(DATOS!$A$1:$A$201,ROW()-12))} | C24: {=IF(INDEX(DATOS!$B$1:$B$201,ROW()-12)="","",INDEX(DATOS!$B$1:$B$201,ROW()-12))} | H24: {=IF(INDEX(DATOS!$C$1:$C$201,ROW()-12)="","",INDEX(DATOS!$C$1:$C$201,ROW()-12))} | I24: {=IF(INDEX(DATOS!$D$1:$D$201,ROW()-12)="","",INDEX(DATOS!$D$1:$D$201,ROW()-12))} | J24: {=IF(INDEX(DATOS!$M$1:$M$201,ROW()-12)="","",INDEX(DATOS!$M$1:$M$201,ROW()-12))} | K24: {=IF(INDEX(DATOS!$K$1:$K$201,ROW()-12)="","",INDEX(DATOS!$K$1:$K$201,ROW()-12))} | L24: {=IF(INDEX(DATOS!$E$1:$E$201,ROW()-12)="","",INDEX(DATOS!$E$1:$E$201,ROW()-12))} | M24: {=IF(INDEX(DATOS!$F$1:$F$201,ROW()-12)="","",INDEX(DATOS!$F$1:$F$201,ROW()-12))} | N24: {=IF(INDEX(DATOS!$G$1:$G$201,ROW()-12)="","",INDEX(DATOS!$G$1:$G$201,ROW()-12))} | O24: {=IF(INDEX(DATOS!$H$1:$H$201,ROW()-12)="","",INDEX(DATOS!$H$1:$H$201,ROW()-12))} | P24: {=IF(INDEX(DATOS!$I$1:$I$201,ROW()-12)="","",INDEX(DATOS!$I$1:$I$201,ROW()-12))} | Q24: {=IF(INDEX(DATOS!$J$1:$J$201,ROW()-12)="","",INDEX(DATOS!$J$1:$J$201,ROW()-12))} | R24: {=IF(INDEX(DATOS!$P$1:$P$201,ROW()-12)="","",INDEX(DATOS!$P$1:$P$201,ROW()-12))} | T24: Vence hoy (0 días) | U24: =COUNTIF(DATOS!$M$2:$M$5001,"=0") | V24: =U24/$U$25
B25: {=IF(INDEX(DATOS!$A$1:$A$201,ROW()-12)="","",INDEX(DATOS!$A$1:$A$201,ROW()-12))} | C25: {=IF(INDEX(DATOS!$B$1:$B$201,ROW()-12)="","",INDEX(DATOS!$B$1:$B$201,ROW()-12))} | H25: {=IF(INDEX(DATOS!$C$1:$C$201,ROW()-12)="","",INDEX(DATOS!$C$1:$C$201,ROW()-12))} | I25: {=IF(INDEX(DATOS!$D$1:$D$201,ROW()-12)="","",INDEX(DATOS!$D$1:$D$201,ROW()-12))} | J25: {=IF(INDEX(DATOS!$M$1:$M$201,ROW()-12)="","",INDEX(DATOS!$M$1:$M$201,ROW()-12))} | K25: {=IF(INDEX(DATOS!$K$1:$K$201,ROW()-12)="","",INDEX(DATOS!$K$1:$K$201,ROW()-12))} | L25: {=IF(INDEX(DATOS!$E$1:$E$201,ROW()-12)="","",INDEX(DATOS!$E$1:$E$201,ROW()-12))} | M25: {=IF(INDEX(DATOS!$F$1:$F$201,ROW()-12)="","",INDEX(DATOS!$F$1:$F$201,ROW()-12))} | N25: {=IF(INDEX(DATOS!$G$1:$G$201,ROW()-12)="","",INDEX(DATOS!$G$1:$G$201,ROW()-12))} | O25: {=IF(INDEX(DATOS!$H$1:$H$201,ROW()-12)="","",INDEX(DATOS!$H$1:$H$201,ROW()-12))} | P25: {=IF(INDEX(DATOS!$I$1:$I$201,ROW()-12)="","",INDEX(DATOS!$I$1:$I$201,ROW()-12))} | Q25: {=IF(INDEX(DATOS!$J$1:$J$201,ROW()-12)="","",INDEX(DATOS!$J$1:$J$201,ROW()-12))} | R25: {=IF(INDEX(DATOS!$P$1:$P$201,ROW()-12)="","",INDEX(DATOS!$P$1:$P$201,ROW()-12))} | T25: TOTAL | U25: =SUM(U22:U24)
B26: {=IF(INDEX(DATOS!$A$1:$A$201,ROW()-12)="","",INDEX(DATOS!$A$1:$A$201,ROW()-12))} | C26: {=IF(INDEX(DATOS!$B$1:$B$201,ROW()-12)="","",INDEX(DATOS!$B$1:$B$201,ROW()-12))} | H26: {=IF(INDEX(DATOS!$C$1:$C$201,ROW()-12)="","",INDEX(DATOS!$C$1:$C$201,ROW()-12))} | I26: {=IF(INDEX(DATOS!$D$1:$D$201,ROW()-12)="","",INDEX(DATOS!$D$1:$D$201,ROW()-12))} | J26: {=IF(INDEX(DATOS!$M$1:$M$201,ROW()-12)="","",INDEX(DATOS!$M$1:$M$201,ROW()-12))} | K26: {=IF(INDEX(DATOS!$K$1:$K$201,ROW()-12)="","",INDEX(DATOS!$K$1:$K$201,ROW()-12))} | L26: {=IF(INDEX(DATOS!$E$1:$E$201,ROW()-12)="","",INDEX(DATOS!$E$1:$E$201,ROW()-12))} | M26: {=IF(INDEX(DATOS!$F$1:$F$201,ROW()-12)="","",INDEX(DATOS!$F$1:$F$201,ROW()-12))} | N26: {=IF(INDEX(DATOS!$G$1:$G$201,ROW()-12)="","",INDEX(DATOS!$G$1:$G$201,ROW()-12))} | O26: {=IF(INDEX(DATOS!$H$1:$H$201,ROW()-12)="","",INDEX(DATOS!$H$1:$H$201,ROW()-12))} | P26: {=IF(INDEX(DATOS!$I$1:$I$201,ROW()-12)="","",INDEX(DATOS!$I$1:$I$201,ROW()-12))} | Q26: {=IF(INDEX(DATOS!$J$1:$J$201,ROW()-12)="","",INDEX(DATOS!$J$1:$J$201,ROW()-12))} | R26: {=IF(INDEX(DATOS!$P$1:$P$201,ROW()-12)="","",INDEX(DATOS!$P$1:$P$201,ROW()-12))}
B27: {=IF(INDEX(DATOS!$A$1:$A$201,ROW()-12)="","",INDEX(DATOS!$A$1:$A$201,ROW()-12))} | C27: {=IF(INDEX(DATOS!$B$1:$B$201,ROW()-12)="","",INDEX(DATOS!$B$1:$B$201,ROW()-12))} | H27: {=IF(INDEX(DATOS!$C$1:$C$201,ROW()-12)="","",INDEX(DATOS!$C$1:$C$201,ROW()-12))} | I27: {=IF(INDEX(DATOS!$D$1:$D$201,ROW()-12)="","",INDEX(DATOS!$D$1:$D$201,ROW()-12))} | J27: {=IF(INDEX(DATOS!$M$1:$M$201,ROW()-12)="","",INDEX(DATOS!$M$1:$M$201,ROW()-12))} | K27: {=IF(INDEX(DATOS!$K$1:$K$201,ROW()-12)="","",INDEX(DATOS!$K$1:$K$201,ROW()-12))} | L27: {=IF(INDEX(DATOS!$E$1:$E$201,ROW()-12)="","",INDEX(DATOS!$E$1:$E$201,ROW()-12))} | M27: {=IF(INDEX(DATOS!$F$1:$F$201,ROW()-12)="","",INDEX(DATOS!$F$1:$F$201,ROW()-12))} | N27: {=IF(INDEX(DATOS!$G$1:$G$201,ROW()-12)="","",INDEX(DATOS!$G$1:$G$201,ROW()-12))} | O27: {=IF(INDEX(DATOS!$H$1:$H$201,ROW()-12)="","",INDEX(DATOS!$H$1:$H$201,ROW()-12))} | P27: {=IF(INDEX(DATOS!$I$1:$I$201,ROW()-12)="","",INDEX(DATOS!$I$1:$I$201,ROW()-12))} | Q27: {=IF(INDEX(DATOS!$J$1:$J$201,ROW()-12)="","",INDEX(DATOS!$J$1:$J$201,ROW()-12))} | R27: {=IF(INDEX(DATOS!$P$1:$P$201,ROW()-12)="","",INDEX(DATOS!$P$1:$P$201,ROW()-12))} | T27: CHECKS PENDIENTES POR ANTIGÜEDAD (TODO EL CORTE)
B28: {=IF(INDEX(DATOS!$A$1:$A$201,ROW()-12)="","",INDEX(DATOS!$A$1:$A$201,ROW()-12))} | C28: {=IF(INDEX(DATOS!$B$1:$B$201,ROW()-12)="","",INDEX(DATOS!$B$1:$B$201,ROW()-12))} | H28: {=IF(INDEX(DATOS!$C$1:$C$201,ROW()-12)="","",INDEX(DATOS!$C$1:$C$201,ROW()-12))} | I28: {=IF(INDEX(DATOS!$D$1:$D$201,ROW()-12)="","",INDEX(DATOS!$D$1:$D$201,ROW()-12))} | J28: {=IF(INDEX(DATOS!$M$1:$M$201,ROW()-12)="","",INDEX(DATOS!$M$1:$M$201,ROW()-12))} | K28: {=IF(INDEX(DATOS!$K$1:$K$201,ROW()-12)="","",INDEX(DATOS!$K$1:$K$201,ROW()-12))} | L28: {=IF(INDEX(DATOS!$E$1:$E$201,ROW()-12)="","",INDEX(DATOS!$E$1:$E$201,ROW()-12))} | M28: {=IF(INDEX(DATOS!$F$1:$F$201,ROW()-12)="","",INDEX(DATOS!$F$1:$F$201,ROW()-12))} | N28: {=IF(INDEX(DATOS!$G$1:$G$201,ROW()-12)="","",INDEX(DATOS!$G$1:$G$201,ROW()-12))} | O28: {=IF(INDEX(DATOS!$H$1:$H$201,ROW()-12)="","",INDEX(DATOS!$H$1:$H$201,ROW()-12))} | P28: {=IF(INDEX(DATOS!$I$1:$I$201,ROW()-12)="","",INDEX(DATOS!$I$1:$I$201,ROW()-12))} | Q28: {=IF(INDEX(DATOS!$J$1:$J$201,ROW()-12)="","",INDEX(DATOS!$J$1:$J$201,ROW()-12))} | R28: {=IF(INDEX(DATOS!$P$1:$P$201,ROW()-12)="","",INDEX(DATOS!$P$1:$P$201,ROW()-12))} | T28: RANGO | U28: CHECKS | V28: %
B29: {=IF(INDEX(DATOS!$A$1:$A$201,ROW()-12)="","",INDEX(DATOS!$A$1:$A$201,ROW()-12))} | C29: {=IF(INDEX(DATOS!$B$1:$B$201,ROW()-12)="","",INDEX(DATOS!$B$1:$B$201,ROW()-12))} | H29: {=IF(INDEX(DATOS!$C$1:$C$201,ROW()-12)="","",INDEX(DATOS!$C$1:$C$201,ROW()-12))} | I29: {=IF(INDEX(DATOS!$D$1:$D$201,ROW()-12)="","",INDEX(DATOS!$D$1:$D$201,ROW()-12))} | J29: {=IF(INDEX(DATOS!$M$1:$M$201,ROW()-12)="","",INDEX(DATOS!$M$1:$M$201,ROW()-12))} | K29: {=IF(INDEX(DATOS!$K$1:$K$201,ROW()-12)="","",INDEX(DATOS!$K$1:$K$201,ROW()-12))} | L29: {=IF(INDEX(DATOS!$E$1:$E$201,ROW()-12)="","",INDEX(DATOS!$E$1:$E$201,ROW()-12))} | M29: {=IF(INDEX(DATOS!$F$1:$F$201,ROW()-12)="","",INDEX(DATOS!$F$1:$F$201,ROW()-12))} | N29: {=IF(INDEX(DATOS!$G$1:$G$201,ROW()-12)="","",INDEX(DATOS!$G$1:$G$201,ROW()-12))} | O29: {=IF(INDEX(DATOS!$H$1:$H$201,ROW()-12)="","",INDEX(DATOS!$H$1:$H$201,ROW()-12))} | P29: {=IF(INDEX(DATOS!$I$1:$I$201,ROW()-12)="","",INDEX(DATOS!$I$1:$I$201,ROW()-12))} | Q29: {=IF(INDEX(DATOS!$J$1:$J$201,ROW()-12)="","",INDEX(DATOS!$J$1:$J$201,ROW()-12))} | R29: {=IF(INDEX(DATOS!$P$1:$P$201,ROW()-12)="","",INDEX(DATOS!$P$1:$P$201,ROW()-12))} | T29: Vencidas > 1 día | U29: =SUMIF(DATOS!$M$2:$M$5001,">1",DATOS!$K$2:$K$5001) | V29: =U29/$U$32
B30: {=IF(INDEX(DATOS!$A$1:$A$201,ROW()-12)="","",INDEX(DATOS!$A$1:$A$201,ROW()-12))} | C30: {=IF(INDEX(DATOS!$B$1:$B$201,ROW()-12)="","",INDEX(DATOS!$B$1:$B$201,ROW()-12))} | H30: {=IF(INDEX(DATOS!$C$1:$C$201,ROW()-12)="","",INDEX(DATOS!$C$1:$C$201,ROW()-12))} | I30: {=IF(INDEX(DATOS!$D$1:$D$201,ROW()-12)="","",INDEX(DATOS!$D$1:$D$201,ROW()-12))} | J30: {=IF(INDEX(DATOS!$M$1:$M$201,ROW()-12)="","",INDEX(DATOS!$M$1:$M$201,ROW()-12))} | K30: {=IF(INDEX(DATOS!$K$1:$K$201,ROW()-12)="","",INDEX(DATOS!$K$1:$K$201,ROW()-12))} | L30: {=IF(INDEX(DATOS!$E$1:$E$201,ROW()-12)="","",INDEX(DATOS!$E$1:$E$201,ROW()-12))} | M30: {=IF(INDEX(DATOS!$F$1:$F$201,ROW()-12)="","",INDEX(DATOS!$F$1:$F$201,ROW()-12))} | N30: {=IF(INDEX(DATOS!$G$1:$G$201,ROW()-12)="","",INDEX(DATOS!$G$1:$G$201,ROW()-12))} | O30: {=IF(INDEX(DATOS!$H$1:$H$201,ROW()-12)="","",INDEX(DATOS!$H$1:$H$201,ROW()-12))} | P30: {=IF(INDEX(DATOS!$I$1:$I$201,ROW()-12)="","",INDEX(DATOS!$I$1:$I$201,ROW()-12))} | Q30: {=IF(INDEX(DATOS!$J$1:$J$201,ROW()-12)="","",INDEX(DATOS!$J$1:$J$201,ROW()-12))} | R30: {=IF(INDEX(DATOS!$P$1:$P$201,ROW()-12)="","",INDEX(DATOS!$P$1:$P$201,ROW()-12))} | T30: Vencidas 1 día | U30: =SUMIFS(DATOS!$K$2:$K$5001,DATOS!$M$2:$M$5001,1) | V30: =U30/$U$32
B31: {=IF(INDEX(DATOS!$A$1:$A$201,ROW()-12)="","",INDEX(DATOS!$A$1:$A$201,ROW()-12))} | C31: {=IF(INDEX(DATOS!$B$1:$B$201,ROW()-12)="","",INDEX(DATOS!$B$1:$B$201,ROW()-12))} | H31: {=IF(INDEX(DATOS!$C$1:$C$201,ROW()-12)="","",INDEX(DATOS!$C$1:$C$201,ROW()-12))} | I31: {=IF(INDEX(DATOS!$D$1:$D$201,ROW()-12)="","",INDEX(DATOS!$D$1:$D$201,ROW()-12))} | J31: {=IF(INDEX(DATOS!$M$1:$M$201,ROW()-12)="","",INDEX(DATOS!$M$1:$M$201,ROW()-12))} | K31: {=IF(INDEX(DATOS!$K$1:$K$201,ROW()-12)="","",INDEX(DATOS!$K$1:$K$201,ROW()-12))} | L31: {=IF(INDEX(DATOS!$E$1:$E$201,ROW()-12)="","",INDEX(DATOS!$E$1:$E$201,ROW()-12))} | M31: {=IF(INDEX(DATOS!$F$1:$F$201,ROW()-12)="","",INDEX(DATOS!$F$1:$F$201,ROW()-12))} | N31: {=IF(INDEX(DATOS!$G$1:$G$201,ROW()-12)="","",INDEX(DATOS!$G$1:$G$201,ROW()-12))} | O31: {=IF(INDEX(DATOS!$H$1:$H$201,ROW()-12)="","",INDEX(DATOS!$H$1:$H$201,ROW()-12))} | P31: {=IF(INDEX(DATOS!$I$1:$I$201,ROW()-12)="","",INDEX(DATOS!$I$1:$I$201,ROW()-12))} | Q31: {=IF(INDEX(DATOS!$J$1:$J$201,ROW()-12)="","",INDEX(DATOS!$J$1:$J$201,ROW()-12))} | R31: {=IF(INDEX(DATOS!$P$1:$P$201,ROW()-12)="","",INDEX(DATOS!$P$1:$P$201,ROW()-12))} | T31: Vence hoy (0 días) | U31: =SUMIFS(DATOS!$K$2:$K$5001,DATOS!$M$2:$M$5001,0) | V31: =U31/$U$32
B32: {=IF(INDEX(DATOS!$A$1:$A$201,ROW()-12)="","",INDEX(DATOS!$A$1:$A$201,ROW()-12))} | C32: {=IF(INDEX(DATOS!$B$1:$B$201,ROW()-12)="","",INDEX(DATOS!$B$1:$B$201,ROW()-12))} | H32: {=IF(INDEX(DATOS!$C$1:$C$201,ROW()-12)="","",INDEX(DATOS!$C$1:$C$201,ROW()-12))} | I32: {=IF(INDEX(DATOS!$D$1:$D$201,ROW()-12)="","",INDEX(DATOS!$D$1:$D$201,ROW()-12))} | J32: {=IF(INDEX(DATOS!$M$1:$M$201,ROW()-12)="","",INDEX(DATOS!$M$1:$M$201,ROW()-12))} | K32: {=IF(INDEX(DATOS!$K$1:$K$201,ROW()-12)="","",INDEX(DATOS!$K$1:$K$201,ROW()-12))} | L32: {=IF(INDEX(DATOS!$E$1:$E$201,ROW()-12)="","",INDEX(DATOS!$E$1:$E$201,ROW()-12))} | M32: {=IF(INDEX(DATOS!$F$1:$F$201,ROW()-12)="","",INDEX(DATOS!$F$1:$F$201,ROW()-12))} | N32: {=IF(INDEX(DATOS!$G$1:$G$201,ROW()-12)="","",INDEX(DATOS!$G$1:$G$201,ROW()-12))} | O32: {=IF(INDEX(DATOS!$H$1:$H$201,ROW()-12)="","",INDEX(DATOS!$H$1:$H$201,ROW()-12))} | P32: {=IF(INDEX(DATOS!$I$1:$I$201,ROW()-12)="","",INDEX(DATOS!$I$1:$I$201,ROW()-12))} | Q32: {=IF(INDEX(DATOS!$J$1:$J$201,ROW()-12)="","",INDEX(DATOS!$J$1:$J$201,ROW()-12))} | R32: {=IF(INDEX(DATOS!$P$1:$P$201,ROW()-12)="","",INDEX(DATOS!$P$1:$P$201,ROW()-12))} | T32: TOTAL | U32: =SUM(U29:U31)
B33: {=IF(INDEX(DATOS!$A$1:$A$201,ROW()-12)="","",INDEX(DATOS!$A$1:$A$201,ROW()-12))} | C33: {=IF(INDEX(DATOS!$B$1:$B$201,ROW()-12)="","",INDEX(DATOS!$B$1:$B$201,ROW()-12))} | H33: {=IF(INDEX(DATOS!$C$1:$C$201,ROW()-12)="","",INDEX(DATOS!$C$1:$C$201,ROW()-12))} | I33: {=IF(INDEX(DATOS!$D$1:$D$201,ROW()-12)="","",INDEX(DATOS!$D$1:$D$201,ROW()-12))} | J33: {=IF(INDEX(DATOS!$M$1:$M$201,ROW()-12)="","",INDEX(DATOS!$M$1:$M$201,ROW()-12))} | K33: {=IF(INDEX(DATOS!$K$1:$K$201,ROW()-12)="","",INDEX(DATOS!$K$1:$K$201,ROW()-12))} | L33: {=IF(INDEX(DATOS!$E$1:$E$201,ROW()-12)="","",INDEX(DATOS!$E$1:$E$201,ROW()-12))} | M33: {=IF(INDEX(DATOS!$F$1:$F$201,ROW()-12)="","",INDEX(DATOS!$F$1:$F$201,ROW()-12))} | N33: {=IF(INDEX(DATOS!$G$1:$G$201,ROW()-12)="","",INDEX(DATOS!$G$1:$G$201,ROW()-12))} | O33: {=IF(INDEX(DATOS!$H$1:$H$201,ROW()-12)="","",INDEX(DATOS!$H$1:$H$201,ROW()-12))} | P33: {=IF(INDEX(DATOS!$I$1:$I$201,ROW()-12)="","",INDEX(DATOS!$I$1:$I$201,ROW()-12))} | Q33: {=IF(INDEX(DATOS!$J$1:$J$201,ROW()-12)="","",INDEX(DATOS!$J$1:$J$201,ROW()-12))} | R33: {=IF(INDEX(DATOS!$P$1:$P$201,ROW()-12)="","",INDEX(DATOS!$P$1:$P$201,ROW()-12))}
B34: {=IF(INDEX(DATOS!$A$1:$A$201,ROW()-12)="","",INDEX(DATOS!$A$1:$A$201,ROW()-12))} | C34: {=IF(INDEX(DATOS!$B$1:$B$201,ROW()-12)="","",INDEX(DATOS!$B$1:$B$201,ROW()-12))} | H34: {=IF(INDEX(DATOS!$C$1:$C$201,ROW()-12)="","",INDEX(DATOS!$C$1:$C$201,ROW()-12))} | I34: {=IF(INDEX(DATOS!$D$1:$D$201,ROW()-12)="","",INDEX(DATOS!$D$1:$D$201,ROW()-12))} | J34: {=IF(INDEX(DATOS!$M$1:$M$201,ROW()-12)="","",INDEX(DATOS!$M$1:$M$201,ROW()-12))} | K34: {=IF(INDEX(DATOS!$K$1:$K$201,ROW()-12)="","",INDEX(DATOS!$K$1:$K$201,ROW()-12))} | L34: {=IF(INDEX(DATOS!$E$1:$E$201,ROW()-12)="","",INDEX(DATOS!$E$1:$E$201,ROW()-12))} | M34: {=IF(INDEX(DATOS!$F$1:$F$201,ROW()-12)="","",INDEX(DATOS!$F$1:$F$201,ROW()-12))} | N34: {=IF(INDEX(DATOS!$G$1:$G$201,ROW()-12)="","",INDEX(DATOS!$G$1:$G$201,ROW()-12))} | O34: {=IF(INDEX(DATOS!$H$1:$H$201,ROW()-12)="","",INDEX(DATOS!$H$1:$H$201,ROW()-12))} | P34: {=IF(INDEX(DATOS!$I$1:$I$201,ROW()-12)="","",INDEX(DATOS!$I$1:$I$201,ROW()-12))} | Q34: {=IF(INDEX(DATOS!$J$1:$J$201,ROW()-12)="","",INDEX(DATOS!$J$1:$J$201,ROW()-12))} | R34: {=IF(INDEX(DATOS!$P$1:$P$201,ROW()-12)="","",INDEX(DATOS!$P$1:$P$201,ROW()-12))} | T34: CHECKS PENDIENTES POR FAMILIA (TODO EL CORTE)
B35: {=IF(INDEX(DATOS!$A$1:$A$201,ROW()-12)="","",INDEX(DATOS!$A$1:$A$201,ROW()-12))} | C35: {=IF(INDEX(DATOS!$B$1:$B$201,ROW()-12)="","",INDEX(DATOS!$B$1:$B$201,ROW()-12))} | H35: {=IF(INDEX(DATOS!$C$1:$C$201,ROW()-12)="","",INDEX(DATOS!$C$1:$C$201,ROW()-12))} | I35: {=IF(INDEX(DATOS!$D$1:$D$201,ROW()-12)="","",INDEX(DATOS!$D$1:$D$201,ROW()-12))} | J35: {=IF(INDEX(DATOS!$M$1:$M$201,ROW()-12)="","",INDEX(DATOS!$M$1:$M$201,ROW()-12))} | K35: {=IF(INDEX(DATOS!$K$1:$K$201,ROW()-12)="","",INDEX(DATOS!$K$1:$K$201,ROW()-12))} | L35: {=IF(INDEX(DATOS!$E$1:$E$201,ROW()-12)="","",INDEX(DATOS!$E$1:$E$201,ROW()-12))} | M35: {=IF(INDEX(DATOS!$F$1:$F$201,ROW()-12)="","",INDEX(DATOS!$F$1:$F$201,ROW()-12))} | N35: {=IF(INDEX(DATOS!$G$1:$G$201,ROW()-12)="","",INDEX(DATOS!$G$1:$G$201,ROW()-12))} | O35: {=IF(INDEX(DATOS!$H$1:$H$201,ROW()-12)="","",INDEX(DATOS!$H$1:$H$201,ROW()-12))} | P35: {=IF(INDEX(DATOS!$I$1:$I$201,ROW()-12)="","",INDEX(DATOS!$I$1:$I$201,ROW()-12))} | Q35: {=IF(INDEX(DATOS!$J$1:$J$201,ROW()-12)="","",INDEX(DATOS!$J$1:$J$201,ROW()-12))} | R35: {=IF(INDEX(DATOS!$P$1:$P$201,ROW()-12)="","",INDEX(DATOS!$P$1:$P$201,ROW()-12))} | T35: FAMILIA | U35: CHECKS | V35: %
B36: {=IF(INDEX(DATOS!$A$1:$A$201,ROW()-12)="","",INDEX(DATOS!$A$1:$A$201,ROW()-12))} | C36: {=IF(INDEX(DATOS!$B$1:$B$201,ROW()-12)="","",INDEX(DATOS!$B$1:$B$201,ROW()-12))} | H36: {=IF(INDEX(DATOS!$C$1:$C$201,ROW()-12)="","",INDEX(DATOS!$C$1:$C$201,ROW()-12))} | I36: {=IF(INDEX(DATOS!$D$1:$D$201,ROW()-12)="","",INDEX(DATOS!$D$1:$D$201,ROW()-12))} | J36: {=IF(INDEX(DATOS!$M$1:$M$201,ROW()-12)="","",INDEX(DATOS!$M$1:$M$201,ROW()-12))} | K36: {=IF(INDEX(DATOS!$K$1:$K$201,ROW()-12)="","",INDEX(DATOS!$K$1:$K$201,ROW()-12))} | L36: {=IF(INDEX(DATOS!$E$1:$E$201,ROW()-12)="","",INDEX(DATOS!$E$1:$E$201,ROW()-12))} | M36: {=IF(INDEX(DATOS!$F$1:$F$201,ROW()-12)="","",INDEX(DATOS!$F$1:$F$201,ROW()-12))} | N36: {=IF(INDEX(DATOS!$G$1:$G$201,ROW()-12)="","",INDEX(DATOS!$G$1:$G$201,ROW()-12))} | O36: {=IF(INDEX(DATOS!$H$1:$H$201,ROW()-12)="","",INDEX(DATOS!$H$1:$H$201,ROW()-12))} | P36: {=IF(INDEX(DATOS!$I$1:$I$201,ROW()-12)="","",INDEX(DATOS!$I$1:$I$201,ROW()-12))} | Q36: {=IF(INDEX(DATOS!$J$1:$J$201,ROW()-12)="","",INDEX(DATOS!$J$1:$J$201,ROW()-12))} | R36: {=IF(INDEX(DATOS!$P$1:$P$201,ROW()-12)="","",INDEX(DATOS!$P$1:$P$201,ROW()-12))} | T36: Acero | U36: =SUMIF(DATOS!$C$2:$C$5001,$T36,DATOS!$K$2:$K$5001) | V36: =U36/$U$42
B37: {=IF(INDEX(DATOS!$A$1:$A$201,ROW()-12)="","",INDEX(DATOS!$A$1:$A$201,ROW()-12))} | C37: {=IF(INDEX(DATOS!$B$1:$B$201,ROW()-12)="","",INDEX(DATOS!$B$1:$B$201,ROW()-12))} | H37: {=IF(INDEX(DATOS!$C$1:$C$201,ROW()-12)="","",INDEX(DATOS!$C$1:$C$201,ROW()-12))} | I37: {=IF(INDEX(DATOS!$D$1:$D$201,ROW()-12)="","",INDEX(DATOS!$D$1:$D$201,ROW()-12))} | J37: {=IF(INDEX(DATOS!$M$1:$M$201,ROW()-12)="","",INDEX(DATOS!$M$1:$M$201,ROW()-12))} | K37: {=IF(INDEX(DATOS!$K$1:$K$201,ROW()-12)="","",INDEX(DATOS!$K$1:$K$201,ROW()-12))} | L37: {=IF(INDEX(DATOS!$E$1:$E$201,ROW()-12)="","",INDEX(DATOS!$E$1:$E$201,ROW()-12))} | M37: {=IF(INDEX(DATOS!$F$1:$F$201,ROW()-12)="","",INDEX(DATOS!$F$1:$F$201,ROW()-12))} | N37: {=IF(INDEX(DATOS!$G$1:$G$201,ROW()-12)="","",INDEX(DATOS!$G$1:$G$201,ROW()-12))} | O37: {=IF(INDEX(DATOS!$H$1:$H$201,ROW()-12)="","",INDEX(DATOS!$H$1:$H$201,ROW()-12))} | P37: {=IF(INDEX(DATOS!$I$1:$I$201,ROW()-12)="","",INDEX(DATOS!$I$1:$I$201,ROW()-12))} | Q37: {=IF(INDEX(DATOS!$J$1:$J$201,ROW()-12)="","",INDEX(DATOS!$J$1:$J$201,ROW()-12))} | R37: {=IF(INDEX(DATOS!$P$1:$P$201,ROW()-12)="","",INDEX(DATOS!$P$1:$P$201,ROW()-12))} | T37: Encofrado | U37: =SUMIF(DATOS!$C$2:$C$5001,$T37,DATOS!$K$2:$K$5001) | V37: =U37/$U$42
B38: {=IF(INDEX(DATOS!$A$1:$A$201,ROW()-12)="","",INDEX(DATOS!$A$1:$A$201,ROW()-12))} | C38: {=IF(INDEX(DATOS!$B$1:$B$201,ROW()-12)="","",INDEX(DATOS!$B$1:$B$201,ROW()-12))} | H38: {=IF(INDEX(DATOS!$C$1:$C$201,ROW()-12)="","",INDEX(DATOS!$C$1:$C$201,ROW()-12))} | I38: {=IF(INDEX(DATOS!$D$1:$D$201,ROW()-12)="","",INDEX(DATOS!$D$1:$D$201,ROW()-12))} | J38: {=IF(INDEX(DATOS!$M$1:$M$201,ROW()-12)="","",INDEX(DATOS!$M$1:$M$201,ROW()-12))} | K38: {=IF(INDEX(DATOS!$K$1:$K$201,ROW()-12)="","",INDEX(DATOS!$K$1:$K$201,ROW()-12))} | L38: {=IF(INDEX(DATOS!$E$1:$E$201,ROW()-12)="","",INDEX(DATOS!$E$1:$E$201,ROW()-12))} | M38: {=IF(INDEX(DATOS!$F$1:$F$201,ROW()-12)="","",INDEX(DATOS!$F$1:$F$201,ROW()-12))} | N38: {=IF(INDEX(DATOS!$G$1:$G$201,ROW()-12)="","",INDEX(DATOS!$G$1:$G$201,ROW()-12))} | O38: {=IF(INDEX(DATOS!$H$1:$H$201,ROW()-12)="","",INDEX(DATOS!$H$1:$H$201,ROW()-12))} | P38: {=IF(INDEX(DATOS!$I$1:$I$201,ROW()-12)="","",INDEX(DATOS!$I$1:$I$201,ROW()-12))} | Q38: {=IF(INDEX(DATOS!$J$1:$J$201,ROW()-12)="","",INDEX(DATOS!$J$1:$J$201,ROW()-12))} | R38: {=IF(INDEX(DATOS!$P$1:$P$201,ROW()-12)="","",INDEX(DATOS!$P$1:$P$201,ROW()-12))} | T38: Concreto | U38: =SUMIF(DATOS!$C$2:$C$5001,$T38,DATOS!$K$2:$K$5001) | V38: =U38/$U$42
B39: {=IF(INDEX(DATOS!$A$1:$A$201,ROW()-12)="","",INDEX(DATOS!$A$1:$A$201,ROW()-12))} | C39: {=IF(INDEX(DATOS!$B$1:$B$201,ROW()-12)="","",INDEX(DATOS!$B$1:$B$201,ROW()-12))} | H39: {=IF(INDEX(DATOS!$C$1:$C$201,ROW()-12)="","",INDEX(DATOS!$C$1:$C$201,ROW()-12))} | I39: {=IF(INDEX(DATOS!$D$1:$D$201,ROW()-12)="","",INDEX(DATOS!$D$1:$D$201,ROW()-12))} | J39: {=IF(INDEX(DATOS!$M$1:$M$201,ROW()-12)="","",INDEX(DATOS!$M$1:$M$201,ROW()-12))} | K39: {=IF(INDEX(DATOS!$K$1:$K$201,ROW()-12)="","",INDEX(DATOS!$K$1:$K$201,ROW()-12))} | L39: {=IF(INDEX(DATOS!$E$1:$E$201,ROW()-12)="","",INDEX(DATOS!$E$1:$E$201,ROW()-12))} | M39: {=IF(INDEX(DATOS!$F$1:$F$201,ROW()-12)="","",INDEX(DATOS!$F$1:$F$201,ROW()-12))} | N39: {=IF(INDEX(DATOS!$G$1:$G$201,ROW()-12)="","",INDEX(DATOS!$G$1:$G$201,ROW()-12))} | O39: {=IF(INDEX(DATOS!$H$1:$H$201,ROW()-12)="","",INDEX(DATOS!$H$1:$H$201,ROW()-12))} | P39: {=IF(INDEX(DATOS!$I$1:$I$201,ROW()-12)="","",INDEX(DATOS!$I$1:$I$201,ROW()-12))} | Q39: {=IF(INDEX(DATOS!$J$1:$J$201,ROW()-12)="","",INDEX(DATOS!$J$1:$J$201,ROW()-12))} | R39: {=IF(INDEX(DATOS!$P$1:$P$201,ROW()-12)="","",INDEX(DATOS!$P$1:$P$201,ROW()-12))} | T39: Trazo | U39: =SUMIF(DATOS!$C$2:$C$5001,$T39,DATOS!$K$2:$K$5001) | V39: =U39/$U$42
B40: {=IF(INDEX(DATOS!$A$1:$A$201,ROW()-12)="","",INDEX(DATOS!$A$1:$A$201,ROW()-12))} | C40: {=IF(INDEX(DATOS!$B$1:$B$201,ROW()-12)="","",INDEX(DATOS!$B$1:$B$201,ROW()-12))} | H40: {=IF(INDEX(DATOS!$C$1:$C$201,ROW()-12)="","",INDEX(DATOS!$C$1:$C$201,ROW()-12))} | I40: {=IF(INDEX(DATOS!$D$1:$D$201,ROW()-12)="","",INDEX(DATOS!$D$1:$D$201,ROW()-12))} | J40: {=IF(INDEX(DATOS!$M$1:$M$201,ROW()-12)="","",INDEX(DATOS!$M$1:$M$201,ROW()-12))} | K40: {=IF(INDEX(DATOS!$K$1:$K$201,ROW()-12)="","",INDEX(DATOS!$K$1:$K$201,ROW()-12))} | L40: {=IF(INDEX(DATOS!$E$1:$E$201,ROW()-12)="","",INDEX(DATOS!$E$1:$E$201,ROW()-12))} | M40: {=IF(INDEX(DATOS!$F$1:$F$201,ROW()-12)="","",INDEX(DATOS!$F$1:$F$201,ROW()-12))} | N40: {=IF(INDEX(DATOS!$G$1:$G$201,ROW()-12)="","",INDEX(DATOS!$G$1:$G$201,ROW()-12))} | O40: {=IF(INDEX(DATOS!$H$1:$H$201,ROW()-12)="","",INDEX(DATOS!$H$1:$H$201,ROW()-12))} | P40: {=IF(INDEX(DATOS!$I$1:$I$201,ROW()-12)="","",INDEX(DATOS!$I$1:$I$201,ROW()-12))} | Q40: {=IF(INDEX(DATOS!$J$1:$J$201,ROW()-12)="","",INDEX(DATOS!$J$1:$J$201,ROW()-12))} | R40: {=IF(INDEX(DATOS!$P$1:$P$201,ROW()-12)="","",INDEX(DATOS!$P$1:$P$201,ROW()-12))} | T40: Relleno | U40: =SUMIF(DATOS!$C$2:$C$5001,$T40,DATOS!$K$2:$K$5001) | V40: =U40/$U$42
B41: {=IF(INDEX(DATOS!$A$1:$A$201,ROW()-12)="","",INDEX(DATOS!$A$1:$A$201,ROW()-12))} | C41: {=IF(INDEX(DATOS!$B$1:$B$201,ROW()-12)="","",INDEX(DATOS!$B$1:$B$201,ROW()-12))} | H41: {=IF(INDEX(DATOS!$C$1:$C$201,ROW()-12)="","",INDEX(DATOS!$C$1:$C$201,ROW()-12))} | I41: {=IF(INDEX(DATOS!$D$1:$D$201,ROW()-12)="","",INDEX(DATOS!$D$1:$D$201,ROW()-12))} | J41: {=IF(INDEX(DATOS!$M$1:$M$201,ROW()-12)="","",INDEX(DATOS!$M$1:$M$201,ROW()-12))} | K41: {=IF(INDEX(DATOS!$K$1:$K$201,ROW()-12)="","",INDEX(DATOS!$K$1:$K$201,ROW()-12))} | L41: {=IF(INDEX(DATOS!$E$1:$E$201,ROW()-12)="","",INDEX(DATOS!$E$1:$E$201,ROW()-12))} | M41: {=IF(INDEX(DATOS!$F$1:$F$201,ROW()-12)="","",INDEX(DATOS!$F$1:$F$201,ROW()-12))} | N41: {=IF(INDEX(DATOS!$G$1:$G$201,ROW()-12)="","",INDEX(DATOS!$G$1:$G$201,ROW()-12))} | O41: {=IF(INDEX(DATOS!$H$1:$H$201,ROW()-12)="","",INDEX(DATOS!$H$1:$H$201,ROW()-12))} | P41: {=IF(INDEX(DATOS!$I$1:$I$201,ROW()-12)="","",INDEX(DATOS!$I$1:$I$201,ROW()-12))} | Q41: {=IF(INDEX(DATOS!$J$1:$J$201,ROW()-12)="","",INDEX(DATOS!$J$1:$J$201,ROW()-12))} | R41: {=IF(INDEX(DATOS!$P$1:$P$201,ROW()-12)="","",INDEX(DATOS!$P$1:$P$201,ROW()-12))} | T41: Excavacion | U41: =SUMIF(DATOS!$C$2:$C$5001,$T41,DATOS!$K$2:$K$5001) | V41: =U41/$U$42
...
